2021-03-08 14:14:04,513 ERROR: Exception on /notifications [GET] [in /home/boris/.local/lib/python3.8/site-packages/flask/app.py:1758]
Traceback (most recent call last):
  File "/home/boris/.local/lib/python3.8/site-packages/sqlalchemy/engine/base.py", line 1178, in _execute_context
    self.dialect.do_execute(
  File "/home/boris/.local/lib/python3.8/site-packages/sqlalchemy/engine/default.py", line 470, in do_execute
    cursor.execute(statement, parameters)
sqlite3.OperationalError: no such table: user

The above exception was the direct cause of the following exception:

Traceback (most recent call last):
  File "/home/boris/.local/lib/python3.8/site-packages/flask/app.py", line 2292, in wsgi_app
    response = self.full_dispatch_request()
  File "/home/boris/.local/lib/python3.8/site-packages/flask/app.py", line 1815, in full_dispatch_request
    rv = self.handle_user_exception(e)
  File "/home/boris/.local/lib/python3.8/site-packages/flask/app.py", line 1718, in handle_user_exception
    reraise(exc_type, exc_value, tb)
  File "/home/boris/.local/lib/python3.8/site-packages/flask/_compat.py", line 35, in reraise
    raise value
  File "/home/boris/.local/lib/python3.8/site-packages/flask/app.py", line 1811, in full_dispatch_request
    rv = self.preprocess_request()
  File "/home/boris/.local/lib/python3.8/site-packages/flask/app.py", line 2087, in preprocess_request
    rv = func()
  File "/media/boris/Файлы/Код/fatolj/latest/app/main/routes.py", line 28, in before_request
    if current_user.is_authenticated:
  File "/home/boris/.local/lib/python3.8/site-packages/werkzeug/local.py", line 347, in __getattr__
    return getattr(self._get_current_object(), name)
  File "/home/boris/.local/lib/python3.8/site-packages/werkzeug/local.py", line 306, in _get_current_object
    return self.__local()
  File "/home/boris/.local/lib/python3.8/site-packages/flask_login/utils.py", line 26, in <lambda>
    current_user = LocalProxy(lambda: _get_user())
  File "/home/boris/.local/lib/python3.8/site-packages/flask_login/utils.py", line 302, in _get_user
    current_app.login_manager._load_user()
  File "/home/boris/.local/lib/python3.8/site-packages/flask_login/login_manager.py", line 317, in _load_user
    return self.reload_user()
  File "/home/boris/.local/lib/python3.8/site-packages/flask_login/login_manager.py", line 279, in reload_user
    user = self.user_callback(user_id)
  File "/media/boris/Файлы/Код/fatolj/latest/app/models.py", line 152, in load_user
    return User.query.get(int(id))
  File "/home/boris/.local/lib/python3.8/site-packages/sqlalchemy/orm/query.py", line 864, in get
    return self._get_impl(ident, loading.load_on_ident)
  File "/home/boris/.local/lib/python3.8/site-packages/sqlalchemy/orm/query.py", line 897, in _get_impl
    return fallback_fn(self, key)
  File "/home/boris/.local/lib/python3.8/site-packages/sqlalchemy/orm/loading.py", line 223, in load_on_ident
    return q.one()
  File "/home/boris/.local/lib/python3.8/site-packages/sqlalchemy/orm/query.py", line 2814, in one
    ret = self.one_or_none()
  File "/home/boris/.local/lib/python3.8/site-packages/sqlalchemy/orm/query.py", line 2784, in one_or_none
    ret = list(self)
  File "/home/boris/.local/lib/python3.8/site-packages/sqlalchemy/orm/query.py", line 2855, in __iter__
    return self._execute_and_instances(context)
  File "/home/boris/.local/lib/python3.8/site-packages/sqlalchemy/orm/query.py", line 2878, in _execute_and_instances
    result = conn.execute(querycontext.statement, self._params)
  File "/home/boris/.local/lib/python3.8/site-packages/sqlalchemy/engine/base.py", line 945, in execute
    return meth(self, multiparams, params)
  File "/home/boris/.local/lib/python3.8/site-packages/sqlalchemy/sql/elements.py", line 263, in _execute_on_connection
    return connection._execute_clauseelement(self, multiparams, params)
  File "/home/boris/.local/lib/python3.8/site-packages/sqlalchemy/engine/base.py", line 1048, in _execute_clauseelement
    ret = self._execute_context(
  File "/home/boris/.local/lib/python3.8/site-packages/sqlalchemy/engine/base.py", line 1184, in _execute_context
    self._handle_dbapi_exception(
  File "/home/boris/.local/lib/python3.8/site-packages/sqlalchemy/engine/base.py", line 1400, in _handle_dbapi_exception
    util.raise_from_cause(
  File "/home/boris/.local/lib/python3.8/site-packages/sqlalchemy/util/compat.py", line 203, in raise_from_cause
    reraise(type(exception), exception, tb=exc_tb, cause=cause)
  File "/home/boris/.local/lib/python3.8/site-packages/sqlalchemy/util/compat.py", line 186, in reraise
    raise value.with_traceback(tb)
  File "/home/boris/.local/lib/python3.8/site-packages/sqlalchemy/engine/base.py", line 1178, in _execute_context
    self.dialect.do_execute(
  File "/home/boris/.local/lib/python3.8/site-packages/sqlalchemy/engine/default.py", line 470, in do_execute
    cursor.execute(statement, parameters)
sqlalchemy.exc.OperationalError: (sqlite3.OperationalError) no such table: user [SQL: 'SELECT user.id AS user_id, user.username AS user_username, user.email AS user_email, user.password_hash AS user_password_hash, user.about_me AS user_about_me, user.last_seen AS user_last_seen, user.last_message_read_time AS user_last_message_read_time \nFROM user \nWHERE user.id = ?'] [parameters: (1,)]
